Workbook

Sheet Mode d'emploi
A1: Idées de posts – Jeunes entrepreneuses genevoises (L'Annexe by RG / Rentes Genevoises)
A3: Comment l'utiliser
A4: 1. Ajoute chaque idée sur une nouvelle ligne de l'onglet « Idées de posts ». Le N° se remplit tout seul.
A5: 2. Remplis toutes les colonnes, sauf les colonnes grisées (N° et Taux d'engagement), calculées automatiquement.
A6: 3. Statut, Persona, Niveau de conscience, Pilier, Canal, Format, Marque, Ton et Validation conformité ont des listes déroulantes.
A7: 4. Pour ajouter une valeur à une liste (ex. un nouveau canal), écris-la en bas de la bonne colonne dans l'onglet « Listes ».
A8: 5. Après publication : passe le statut à « Publié » et remplis Portée, Interactions et Clics. Le taux d'engagement se calcule tout seul.
A9: 6. L'onglet « Tableau de bord » montre la répartition des idées et compare le mix de contenu aux objectifs (cellules bleues modifiables).
A10: 7. Les filtres de la ligne d'en-tête permettent de trier par persona, canal, statut, etc.
A12: Les 19 idées déjà saisies sont des exemples issus de notre travail : modifie-les, supprime-les ou ajoutes-en.
A14: Repères
A15: Personas : Inès, 27 ans, fondatrice de start-up · Maya, 24 ans, freelance qui démarre · Sofia, 32 ans, praticienne qui s'installe.
... A25: • Case orange dans « Validation conformité » = idée pas encore validée.

Sheet Idées de posts
A1: N° | B1: Date prévue | C1: Statut | D1: Titre / accroche | E1: Angle / description | F1: Persona | G1: Niveau de conscience | H1: Pilier de contenu | I1: Canal | J1: Format | K1: Marque | L1: Ton | M1: Call-to-action | N1: Chiffre utilisé + source | O1: Validation conformité | P1: Responsable | Q1: Lien visuel / brouillon | R1: Portée | S1: Interactions | T1: Taux d'engagement | U1: Clics | V1: Notes / apprentissages
A2: =IF(D2="","",ROW()-1) | C2: Idée | D2: Entrepreneuse à Genève ? Voici le salaire que personne ne te versera à 65 ans. | E2: Accroche choc : montrer l'écart entre l'AVS seule et les besoins réels. Pas de produit. | F2: Maya (freelance) | G2: 1 - Pas consciente | H2: Inspiration | I2: Instagram | J2: Reel | K2: L'Annexe by RG | L2: Tu | M2: Suivre @lannexebyrg | O2: À faire | T2: =IF(OR(R2="",R2=0),"",S2/R2)
A3: =IF(D3="","",ROW()-1) | C3: Idée | D3: Moi qui gère 12 clients en freelance vs moi à 65 ans sans prévoyance | E3: Mème « vie d'indépendante », humour, très partageable. | F3: Maya (freelance) | G3: 1 - Pas consciente | H3: Inspiration | I3: TikTok | J3: Mème | K3: L'Annexe by RG | L3: Tu | M3: Partager à une amie freelance | O3: À faire | T3: =IF(OR(R3="",R3=0),"",S3/R3)
A4: =IF(D4="","",ROW()-1) | C4: Idée | D4: Tu as un business plan pour ta boîte. Et pour toi ? | E4: Post court : parallèle entre gestion d'entreprise et prévoyance perso. | F4: Inès (fondatrice start-up) | G4: 1 - Pas consciente | H4: Inspiration | I4: LinkedIn | J4: Post image | K4: L'Annexe by RG | L4: Tu | M4: Commenter | O4: À faire | T4: =IF(OR(R4="",R4=0),"",S4/R4)
A5: =IF(D5="","",ROW()-1) | C5: Idée | D5: Salariée : 3 piliers. Indépendante : à toi de construire le 2e. | E5: Schéma des 3 piliers avec le 2e « vide » (campagne Le pilier manquant). | F5: Maya (freelance) | G5: 2 - Consciente du problème | H5: Éducation | I5: Instagram | J5: Carrousel | K5: L'Annexe by RG | L5: Tu | M5: Télécharger le guide | N5: CHSS, K. Pärli, 15.02.2024 – 2e pilier facultatif pour les indépendants | O5: À faire | T5: =IF(OR(R5="",R5=0),"",S5/R5)
A6: =IF(D6="","",ROW()-1) | C6: Idée | D6: Les femmes touchent 30,8 % de rente en moins. Voici comment ne pas en faire partie. | E6: Chiffre OFS, ton solidaire, focus sur ce qu'on peut faire (pas de culpabilisation). | F6: Toutes | G6: 2 - Consciente du problème | H6: Éducation | I6: LinkedIn | J6: Carrousel | K6: Rentes Genevoises | L6: Vous | M6: Lire l'article | N6: OFS, Indicateurs de l'égalité 2/2024 (données 2022) – bfs.admin.ch/news/fr/2024-0566 | O6: À faire | T6: =IF(OR(R6="",R6=0),"",S6/R6)
A7: =IF(D7="","",ROW()-1) | C7: Idée | D7: Freelance : personne ne cotise pour toi. Voici comment faire, en 3 étapes. | E7: Face caméra, 3 étapes : comprendre, calculer, ouvrir. | F7: Maya (freelance) | G7: 2 - Consciente du problème | H7: Éducation | I7: TikTok | J7: Vidéo | K7: L'Annexe by RG | L7: Tu | M7: Tester le simulateur | O7: À faire | T7: =IF(OR(R7="",R7=0),"",S7/R7)
A8: =IF(D8="","",ROW()-1) | C8: Idée | D8: Maternité, pause, reconversion : ta prévoyance ne doit pas s'arrêter. | E8: Parcours non linéaires, avec une experte. Peut devenir un live. | F8: Sofia (praticienne) | G8: 2 - Consciente du problème | H8: Éducation | I8: Instagram | J8: Carrousel | K8: L'Annexe by RG | L8: Tu | M8: S'inscrire au live | O8: À faire | T8: =IF(OR(R8="",R8=0),"",S8/R8)
A9: =IF(D9="","",ROW()-1) | C9: Idée | D9: Tu paies tes fournisseurs. Et toi, quand te paies-tu pour plus tard ? | E9: Campagne Payez-vous aussi : la prévoyance comme une ligne du budget. | F9: Inès (fondatrice start-up) | G9: 2 - Consciente du problème | H9: Inspiration | I9: Instagram | J9: Post image | K9: L'Annexe by RG | L9: Tu | M9: Calculer mon économie d'impôt | O9: À faire | T9: =IF(OR(R9="",R9=0),"",S9/R9)
A10: =IF(D10="","",ROW()-1) | C10: Idée | D10: Indépendante sans caisse de pension ? Tu peux déduire jusqu'à 20 % de ton revenu. | E10: Rendre l'avantage fiscal concret avec un exemple en CHF. | F10: Sofia (praticienne) | G10: 3 - Connaît les solutions | H10: Éducation | I10: Instagram | J10: Reel | K10: L'Annexe by RG | L10: Tu | M10: Tester le simulateur | N10: Plafonds 3a 2026 : 7'258 / 36'288 CHF, 20 % du revenu (à valider en interne) | O10: À faire | T10: =IF(OR(R10="",R10=0),"",S10/R10)
A11: =IF(D11="","",ROW()-1) | C11: Idée | D11: 3a ou 3b ? Le guide en 60 secondes pour les indépendantes. | E11: Différences simples : fiscalité, disponibilité, flexibilité. | F11: Toutes | G11: 3 - Connaît les solutions | H11: Éducation | I11: Instagram | J11: Reel | K11: L'Annexe by RG | L11: Tu | M11: Télécharger le guide | O11: À faire | T11: =IF(OR(R11="",R11=0),"",S11/R11)
A12: =IF(D12="","",ROW()-1) | C12: Idée | D12: Revenus irréguliers ? Ta prévoyance peut l'être aussi. | E12: Campagne Même les mois creux. VÉRIFIER la flexibilité des versements avec le produit. | F12: Sofia (praticienne) | G12: 3 - Connaît les solutions | H12: Éducation | I12: Instagram | J12: Carrousel | K12: L'Annexe by RG | L12: Tu | M12: Voir comment ça marche | O12: À faire | T12: =IF(OR(R12="",R12=0),"",S12/R12)
A13: =IF(D13="","",ROW()-1) | C13: Idée | D13: Si je mets 100 CHF par mois dès 25 ans, j'aurai quoi à 65 ans ? | E13: Story sondage, puis réponse avec le simulateur capital 3a de L'Annexe. | F13: Maya (freelance) | G13: 3 - Connaît les solutions | H13: Éducation | I13: Instagram | J13: Story | K13: L'Annexe by RG | L13: Tu | M13: Ouvrir le simulateur | O13: À faire | T13: =IF(OR(R13="",R13=0),"",S13/R13)
A14: =IF(D14="","",ROW()-1) | C14: Idée | D14: J'ai lancé ma boîte à 26 ans. Et j'ai ouvert mon 3a la même année. | E14: Témoignage d'une vraie cliente (consentement écrit). | F14: Inès (fondatrice start-up) | G14: 4 - Connaît RG | H14: Preuve / Marque | I14: Instagram | J14: Reel | K14: L'Annexe by RG | L14: Tu | M14: Prendre rendez-vous | O14: À faire | T14: =IF(OR(R14="",R14=0),"",S14/R14)
A15: =IF(D15="","",ROW()-1) | C15: Idée | D15: Pourquoi une institution genevoise née en 1849 parle aux fondatrices d'aujourd'hui | E15: Mutuelle, pas d'actionnaires, conseil humain, ancrage local. | F15: Toutes | G15: 4 - Connaît RG | H15: Preuve / Marque | I15: LinkedIn | J15: Vidéo | K15: Rentes Genevoises | L15: Vous | M15: Découvrir L'Annexe | N15: rentesgenevoises.ch – « À vos côtés depuis 1849 » | O15: À faire | T15: =IF(OR(R15="",R15=0),"",S15/R15)
A16: =IF(D16="","",ROW()-1) | C16: Idée | D16: Dans les coulisses de L'Annexe : rencontre avec notre conseillère indépendantes | E16: Un visage humain, un prénom, ce qu'elle fait concrètement. | F16: Toutes | G16: 4 - Connaît RG | H16: Preuve / Marque | I16: Instagram | J16: Story | K16: L'Annexe by RG | L16: Tu | M16: Poser une question | O16: À faire | T16: =IF(OR(R16="",R16=0),"",S16/R16)
A17: =IF(D17="","",ROW()-1) | C17: Idée | D17: Midi prévoyance : 1 heure, 10 entrepreneuses, zéro jargon. | E17: Promo de l'événement mensuel à L'Annexe (Rue du Port 3). | F17: Inès (fondatrice start-up) | G17: 4 - Connaît RG | H17: Conversion | I17: LinkedIn | J17: Post image | K17: L'Annexe by RG | L17: Tu | M17: Réserver ma place | O17: À faire | T17: =IF(OR(R17="",R17=0),"",S17/R17)
A18: =IF(D18="","",ROW()-1) | C18: Idée | D18: Une question sur ta prévoyance ? Écris-nous sur WhatsApp, réponse en 24 h. | E18: Faire connaître le canal WhatsApp de L'Annexe. | F18: Sofia (praticienne) | G18: 4 - Connaît RG | H18: Conversion | I18: Instagram | J18: Story | K18: L'Annexe by RG | L18: Tu | M18: Écrire sur WhatsApp | O18: À faire | T18: =IF(OR(R18="",R18=0),"",S18/R18)
A19: =IF(D19="","",ROW()-1) | C19: Idée | D19: 31 décembre : dernière chance de réduire tes impôts de l'année. | E19: Rappel fiscal, urgence douce. Publier fin novembre et mi-décembre. | F19: Toutes | G19: 5 - Prête | H19: Conversion | I19: Instagram | J19: Story | K19: L'Annexe by RG | L19: Tu | M19: Prendre rendez-vous | N19: Plafonds 3a 2026 : 7'258 / 36'288 CHF, 20 % du revenu (à valider en interne) | O19: À faire | T19: =IF(OR(R19="",R19=0),"",S19/R19)
A20: =IF(D20="","",ROW()-1) | C20: Idée | D20: Il te reste jusqu'au 31 décembre pour verser sur ton 3a | E20: Newsletter de novembre avec lien simulateur + RDV. | F20: Toutes | G20: 5 - Prête | H20: Conversion | I20: Newsletter | J20: E-mail | K20: L'Annexe by RG | L20: Tu | M20: Prendre rendez-vous | N20: Plafonds 3a 2026 : 7'258 / 36'288 CHF, 20 % du revenu (à valider en interne) | O20: À faire | T20: =IF(OR(R20="",R20=0),"",S20/R20)
A21: =IF(D21="","",ROW()-1) | T21: =IF(OR(R21="",R21=0),"",S21/R21)
A22: =IF(D22="","",ROW()-1) | T22: =IF(OR(R22="",R22=0),"",S22/R22)
A23: =IF(D23="","",ROW()-1) | T23: =IF(OR(R23="",R23=0),"",S23/R23)
A24: =IF(D24="","",ROW()-1) | T24: =IF(OR(R24="",R24=0),"",S24/R24)
A25: =IF(D25="","",ROW()-1) | T25: =IF(OR(R25="",R25=0),"",S25/R25)
A26: =IF(D26="","",ROW()-1) | T26: =IF(OR(R26="",R26=0),"",S26/R26)
A27: =IF(D27="","",ROW()-1) | T27: =IF(OR(R27="",R27=0),"",S27/R27)
A28: =IF(D28="","",ROW()-1) | T28: =IF(OR(R28="",R28=0),"",S28/R28)
A29: =IF(D29="","",ROW()-1) | T29: =IF(OR(R29="",R29=0),"",S29/R29)
A30: =IF(D30="","",ROW()-1) | T30: =IF(OR(R30="",R30=0),"",S30/R30)
A31: =IF(D31="","",ROW()-1) | T31: =IF(OR(R31="",R31=0),"",S31/R31)
A32: =IF(D32="","",ROW()-1) | T32: =IF(OR(R32="",R32=0),"",S32/R32)
... A300: =IF(D300="","",ROW()-1) | T300: =IF(OR(R300="",R300=0),"",S300/R300)

Sheet Tableau de bord
A1: Tableau de bord des idées de posts
A2: Calculé automatiquement à partir de l'onglet « Idées de posts ». Seules les cellules bleues (objectifs) sont modifiables.
A4: Nombre total d'idées | B4: =COUNTA('Idées de posts'!$D$2:$D$300)
A6: Par statut | B6: Nombre | C6: Part
A7: Idée | B7: =COUNTIF('Idées de posts'!$C$2:$C$300,A7) | C7: =IF($B$4=0,0,B7/$B$4)
A8: À rédiger | B8: =COUNTIF('Idées de posts'!$C$2:$C$300,A8) | C8: =IF($B$4=0,0,B8/$B$4)
A9: En création visuelle | B9: =COUNTIF('Idées de posts'!$C$2:$C$300,A9) | C9: =IF($B$4=0,0,B9/$B$4)
A10: En validation | B10: =COUNTIF('Idées de posts'!$C$2:$C$300,A10) | C10: =IF($B$4=0,0,B10/$B$4)
A11: Validé | B11: =COUNTIF('Idées de posts'!$C$2:$C$300,A11) | C11: =IF($B$4=0,0,B11/$B$4)
A12: Programmé | B12: =COUNTIF('Idées de posts'!$C$2:$C$300,A12) | C12: =IF($B$4=0,0,B12/$B$4)
A13: Publié | B13: =COUNTIF('Idées de posts'!$C$2:$C$300,A13) | C13: =IF($B$4=0,0,B13/$B$4)
A14: Abandonné | B14: =COUNTIF('Idées de posts'!$C$2:$C$300,A14) | C14: =IF($B$4=0,0,B14/$B$4)
A16: Par persona | B16: Nombre | C16: Part
A17: Inès (fondatrice start-up) | B17: =COUNTIF('Idées de posts'!$F$2:$F$300,A17) | C17: =IF($B$4=0,0,B17/$B$4)
A18: Maya (freelance) | B18: =COUNTIF('Idées de posts'!$F$2:$F$300,A18) | C18: =IF($B$4=0,0,B18/$B$4)
A19: Sofia (praticienne) | B19: =COUNTIF('Idées de posts'!$F$2:$F$300,A19) | C19: =IF($B$4=0,0,B19/$B$4)
A20: Toutes | B20: =COUNTIF('Idées de posts'!$F$2:$F$300,A20) | C20: =IF($B$4=0,0,B20/$B$4)
A22: Par niveau de conscience | B22: Nombre | C22: Part
A23: 1 - Pas consciente | B23: =COUNTIF('Idées de posts'!$G$2:$G$300,A23) | C23: =IF($B$4=0,0,B23/$B$4)
A24: 2 - Consciente du problème | B24: =COUNTIF('Idées de posts'!$G$2:$G$300,A24) | C24: =IF($B$4=0,0,B24/$B$4)
A25: 3 - Connaît les solutions | B25: =COUNTIF('Idées de posts'!$G$2:$G$300,A25) | C25: =IF($B$4=0,0,B25/$B$4)
A26: 4 - Connaît RG | B26: =COUNTIF('Idées de posts'!$G$2:$G$300,A26) | C26: =IF($B$4=0,0,B26/$B$4)
A27: 5 - Prête | B27: =COUNTIF('Idées de posts'!$G$2:$G$300,A27) | C27: =IF($B$4=0,0,B27/$B$4)
A28: Niveaux 1 à 3 (objectif ≈ 60 %) | C28: =SUM(C23:C25)
A30: Par pilier de contenu | B30: Nombre | C30: Part | D30: Objectif | E30: Écart
A31: Inspiration | B31: =COUNTIF('Idées de posts'!$H$2:$H$300,A31) | C31: =IF($B$4=0,0,B31/$B$4) | D31: 0.4 | E31: =C31-D31
A32: Éducation | B32: =COUNTIF('Idées de posts'!$H$2:$H$300,A32) | C32: =IF($B$4=0,0,B32/$B$4) | D32: 0.3 | E32: =C32-D32
A33: Preuve / Marque | B33: =COUNTIF('Idées de posts'!$H$2:$H$300,A33) | C33: =IF($B$4=0,0,B33/$B$4) | D33: 0.2 | E33: =C33-D33
A34: Conversion | B34: =COUNTIF('Idées de posts'!$H$2:$H$300,A34) | C34: =IF($B$4=0,0,B34/$B$4) | D34: 0.1 | E34: =C34-D34
A35: Objectifs en bleu = mix recommandé, modifiable.
A37: Par canal | B37: Nombre | C37: Part
A38: Instagram | B38: =COUNTIF('Idées de posts'!$I$2:$I$300,A38) | C38: =IF($B$4=0,0,B38/$B$4)
A39: LinkedIn | B39: =COUNTIF('Idées de posts'!$I$2:$I$300,A39) | C39: =IF($B$4=0,0,B39/$B$4)
A40: TikTok | B40: =COUNTIF('Idées de posts'!$I$2:$I$300,A40) | C40: =IF($B$4=0,0,B40/$B$4)
A41: Newsletter | B41: =COUNTIF('Idées de posts'!$I$2:$I$300,A41) | C41: =IF($B$4=0,0,B41/$B$4)
A42: WhatsApp | B42: =COUNTIF('Idées de posts'!$I$2:$I$300,A42) | C42: =IF($B$4=0,0,B42/$B$4)
A43: Événement | B43: =COUNTIF('Idées de posts'!$I$2:$I$300,A43) | C43: =IF($B$4=0,0,B43/$B$4)
A44: Blog L'Annexe | B44: =COUNTIF('Idées de posts'!$I$2:$I$300,A44) | C44: =IF($B$4=0,0,B44/$B$4)
A46: Par marque | B46: Nombre | C46: Part
A47: L'Annexe by RG | B47: =COUNTIF('Idées de posts'!$K$2:$K$300,A47) | C47: =IF($B$4=0,0,B47/$B$4)
...

Sheet Listes
A1: Statut | B1: Persona | C1: Niveau de conscience | D1: Pilier | E1: Canal | F1: Format | G1: Marque | H1: Ton | I1: Conformité
A2: Idée | B2: Inès (fondatrice start-up) | C2: 1 - Pas consciente | D2: Inspiration | E2: Instagram | F2: Reel | G2: L'Annexe by RG | H2: Tu | I2: À faire
A3: À rédiger | B3: Maya (freelance) | C3: 2 - Consciente du problème | D3: Éducation | E3: LinkedIn | F3: Carrousel | G3: Rentes Genevoises | H3: Vous | I3: En cours
A4: En création visuelle | B4: Sofia (praticienne) | C4: 3 - Connaît les solutions | D4: Preuve / Marque | E4: TikTok | F4: Post image | I4: Validé
A5: En validation | B5: Toutes | C5: 4 - Connaît RG | D5: Conversion | E5: Newsletter | F5: Story | I5: Non requis
A6: Validé | C6: 5 - Prête | E6: WhatsApp | F6: Vidéo
A7: Programmé | E7: Événement | F7: Live
A8: Publié | E8: Blog L'Annexe | F8: Article
A9: Abandonné | F9: E-mail
F10: Mème
